[
  "ERROR ingesting 'TESTCCLW.executive.1332.1547': Traceback (most recent call last):\n  File \"/usr/local/lib/python3.9/site-packages/tenacity/__init__.py\", line 382, in __call__\n    result = fn(*args, **kwargs)\n  File \"/navigator-data-ingest/src/navigator_data_ingest/base/api_client.py\", line 175, in update_document_details\n    token = get_machine_user_token()\n  File \"/navigator-data-ingest/src/navigator_data_ingest/base/api_client.py\", line 49, in get_machine_user_token\n    get_token_response = requests.post(f\"{api_host}/api/tokens\", data=login_data)\n  File \"/usr/local/lib/python3.9/site-packages/requests/api.py\", line 115, in post\n    return request(\"post\", url, data=data, json=json, **kwargs)\n  File \"/usr/local/lib/python3.9/site-packages/requests/api.py\", line 59, in request\n    return session.request(method=method, url=url, **kwargs)\n  File \"/usr/local/lib/python3.9/site-packages/requests/sessions.py\", line 573, in request\n    prep = self.prepare_request(req)\n  File \"/usr/local/lib/python3.9/site-packages/requests/sessions.py\", line 484, in prepare_request\n    p.prepare(\n  File \"/usr/local/lib/python3.9/site-packages/requests/models.py\", line 368, in prepare\n    self.prepare_url(url, params)\n  File \"/usr/local/lib/python3.9/site-packages/requests/models.py\", line 439, in prepare_url\n    raise MissingSchema(\nrequests.exceptions.MissingSchema: Invalid URL '/api/tokens': No scheme supplied. Perhaps you meant https:///api/tokens?\n\nThe above exception was the direct cause of the following exception:\n\nTraceback (most recent call last):\n  File \"/navigator-data-ingest/src/navigator_data_ingest/base/new_document_actions.py\", line 142, in _handle_document\n    update_document_details(\n  File \"/usr/local/lib/python3.9/site-packages/tenacity/__init__.py\", line 289, in wrapped_f\n    return self(f, *args, **kw)\n  File \"/usr/local/lib/python3.9/site-packages/tenacity/__init__.py\", line 379, in __call__\n    do = self.iter(retry_state=retry_state)\n  File \"/usr/local/lib/python3.9/site-packages/tenacity/__init__.py\", line 326, in iter\n    raise retry_exc from fut.exception()\ntenacity.RetryError: RetryError[<Future at 0x7febbdf80f70 state=finished raised MissingSchema>]\n",
  "ERROR ingesting 'TESTCCLW.executive.1332.1550': Traceback (most recent call last):\n  File \"/usr/local/lib/python3.9/site-packages/tenacity/__init__.py\", line 382, in __call__\n    result = fn(*args, **kwargs)\n  File \"/navigator-data-ingest/src/navigator_data_ingest/base/api_client.py\", line 175, in update_document_details\n    token = get_machine_user_token()\n  File \"/navigator-data-ingest/src/navigator_data_ingest/base/api_client.py\", line 49, in get_machine_user_token\n    get_token_response = requests.post(f\"{api_host}/api/tokens\", data=login_data)\n  File \"/usr/local/lib/python3.9/site-packages/requests/api.py\", line 115, in post\n    return request(\"post\", url, data=data, json=json, **kwargs)\n  File \"/usr/local/lib/python3.9/site-packages/requests/api.py\", line 59, in request\n    return session.request(method=method, url=url, **kwargs)\n  File \"/usr/local/lib/python3.9/site-packages/requests/sessions.py\", line 573, in request\n    prep = self.prepare_request(req)\n  File \"/usr/local/lib/python3.9/site-packages/requests/sessions.py\", line 484, in prepare_request\n    p.prepare(\n  File \"/usr/local/lib/python3.9/site-packages/requests/models.py\", line 368, in prepare\n    self.prepare_url(url, params)\n  File \"/usr/local/lib/python3.9/site-packages/requests/models.py\", line 439, in prepare_url\n    raise MissingSchema(\nrequests.exceptions.MissingSchema: Invalid URL '/api/tokens': No scheme supplied. Perhaps you meant https:///api/tokens?\n\nThe above exception was the direct cause of the following exception:\n\nTraceback (most recent call last):\n  File \"/navigator-data-ingest/src/navigator_data_ingest/base/new_document_actions.py\", line 142, in _handle_document\n    update_document_details(\n  File \"/usr/local/lib/python3.9/site-packages/tenacity/__init__.py\", line 289, in wrapped_f\n    return self(f, *args, **kw)\n  File \"/usr/local/lib/python3.9/site-packages/tenacity/__init__.py\", line 379, in __call__\n    do = self.iter(retry_state=retry_state)\n  File \"/usr/local/lib/python3.9/site-packages/tenacity/__init__.py\", line 326, in iter\n    raise retry_exc from fut.exception()\ntenacity.RetryError: RetryError[<Future at 0x7febbeff9220 state=finished raised MissingSchema>]\n",
  "ERROR ingesting 'TESTCCLW.executive.1332.1549': Traceback (most recent call last):\n  File \"/usr/local/lib/python3.9/site-packages/tenacity/__init__.py\", line 382, in __call__\n    result = fn(*args, **kwargs)\n  File \"/navigator-data-ingest/src/navigator_data_ingest/base/api_client.py\", line 175, in update_document_details\n    token = get_machine_user_token()\n  File \"/navigator-data-ingest/src/navigator_data_ingest/base/api_client.py\", line 49, in get_machine_user_token\n    get_token_response = requests.post(f\"{api_host}/api/tokens\", data=login_data)\n  File \"/usr/local/lib/python3.9/site-packages/requests/api.py\", line 115, in post\n    return request(\"post\", url, data=data, json=json, **kwargs)\n  File \"/usr/local/lib/python3.9/site-packages/requests/api.py\", line 59, in request\n    return session.request(method=method, url=url, **kwargs)\n  File \"/usr/local/lib/python3.9/site-packages/requests/sessions.py\", line 573, in request\n    prep = self.prepare_request(req)\n  File \"/usr/local/lib/python3.9/site-packages/requests/sessions.py\", line 484, in prepare_request\n    p.prepare(\n  File \"/usr/local/lib/python3.9/site-packages/requests/models.py\", line 368, in prepare\n    self.prepare_url(url, params)\n  File \"/usr/local/lib/python3.9/site-packages/requests/models.py\", line 439, in prepare_url\n    raise MissingSchema(\nrequests.exceptions.MissingSchema: Invalid URL '/api/tokens': No scheme supplied. Perhaps you meant https:///api/tokens?\n\nThe above exception was the direct cause of the following exception:\n\nTraceback (most recent call last):\n  File \"/navigator-data-ingest/src/navigator_data_ingest/base/new_document_actions.py\", line 142, in _handle_document\n    update_document_details(\n  File \"/usr/local/lib/python3.9/site-packages/tenacity/__init__.py\", line 289, in wrapped_f\n    return self(f, *args, **kw)\n  File \"/usr/local/lib/python3.9/site-packages/tenacity/__init__.py\", line 379, in __call__\n    do = self.iter(retry_state=retry_state)\n  File \"/usr/local/lib/python3.9/site-packages/tenacity/__init__.py\", line 326, in iter\n    raise retry_exc from fut.exception()\ntenacity.RetryError: RetryError[<Future at 0x7febbf0b3160 state=finished raised MissingSchema>]\n",
  "ERROR ingesting 'TESTCCLW.executive.1332.1548': Traceback (most recent call last):\n  File \"/usr/local/lib/python3.9/site-packages/tenacity/__init__.py\", line 382, in __call__\n    result = fn(*args, **kwargs)\n  File \"/navigator-data-ingest/src/navigator_data_ingest/base/api_client.py\", line 175, in update_document_details\n    token = get_machine_user_token()\n  File \"/navigator-data-ingest/src/navigator_data_ingest/base/api_client.py\", line 49, in get_machine_user_token\n    get_token_response = requests.post(f\"{api_host}/api/tokens\", data=login_data)\n  File \"/usr/local/lib/python3.9/site-packages/requests/api.py\", line 115, in post\n    return request(\"post\", url, data=data, json=json, **kwargs)\n  File \"/usr/local/lib/python3.9/site-packages/requests/api.py\", line 59, in request\n    return session.request(method=method, url=url, **kwargs)\n  File \"/usr/local/lib/python3.9/site-packages/requests/sessions.py\", line 573, in request\n    prep = self.prepare_request(req)\n  File \"/usr/local/lib/python3.9/site-packages/requests/sessions.py\", line 484, in prepare_request\n    p.prepare(\n  File \"/usr/local/lib/python3.9/site-packages/requests/models.py\", line 368, in prepare\n    self.prepare_url(url, params)\n  File \"/usr/local/lib/python3.9/site-packages/requests/models.py\", line 439, in prepare_url\n    raise MissingSchema(\nrequests.exceptions.MissingSchema: Invalid URL '/api/tokens': No scheme supplied. Perhaps you meant https:///api/tokens?\n\nThe above exception was the direct cause of the following exception:\n\nTraceback (most recent call last):\n  File \"/navigator-data-ingest/src/navigator_data_ingest/base/new_document_actions.py\", line 142, in _handle_document\n    update_document_details(\n  File \"/usr/local/lib/python3.9/site-packages/tenacity/__init__.py\", line 289, in wrapped_f\n    return self(f, *args, **kw)\n  File \"/usr/local/lib/python3.9/site-packages/tenacity/__init__.py\", line 379, in __call__\n    do = self.iter(retry_state=retry_state)\n  File \"/usr/local/lib/python3.9/site-packages/tenacity/__init__.py\", line 326, in iter\n    raise retry_exc from fut.exception()\ntenacity.RetryError: RetryError[<Future at 0x7febbeff9550 state=finished raised MissingSchema>]\n",
  "ERROR ingesting 'TESTCCLW.executive.1332.1551': Traceback (most recent call last):\n  File \"/usr/local/lib/python3.9/site-packages/tenacity/__init__.py\", line 382, in __call__\n    result = fn(*args, **kwargs)\n  File \"/navigator-data-ingest/src/navigator_data_ingest/base/api_client.py\", line 175, in update_document_details\n    token = get_machine_user_token()\n  File \"/navigator-data-ingest/src/navigator_data_ingest/base/api_client.py\", line 49, in get_machine_user_token\n    get_token_response = requests.post(f\"{api_host}/api/tokens\", data=login_data)\n  File \"/usr/local/lib/python3.9/site-packages/requests/api.py\", line 115, in post\n    return request(\"post\", url, data=data, json=json, **kwargs)\n  File \"/usr/local/lib/python3.9/site-packages/requests/api.py\", line 59, in request\n    return session.request(method=method, url=url, **kwargs)\n  File \"/usr/local/lib/python3.9/site-packages/requests/sessions.py\", line 573, in request\n    prep = self.prepare_request(req)\n  File \"/usr/local/lib/python3.9/site-packages/requests/sessions.py\", line 484, in prepare_request\n    p.prepare(\n  File \"/usr/local/lib/python3.9/site-packages/requests/models.py\", line 368, in prepare\n    self.prepare_url(url, params)\n  File \"/usr/local/lib/python3.9/site-packages/requests/models.py\", line 439, in prepare_url\n    raise MissingSchema(\nrequests.exceptions.MissingSchema: Invalid URL '/api/tokens': No scheme supplied. Perhaps you meant https:///api/tokens?\n\nThe above exception was the direct cause of the following exception:\n\nTraceback (most recent call last):\n  File \"/navigator-data-ingest/src/navigator_data_ingest/base/new_document_actions.py\", line 142, in _handle_document\n    update_document_details(\n  File \"/usr/local/lib/python3.9/site-packages/tenacity/__init__.py\", line 289, in wrapped_f\n    return self(f, *args, **kw)\n  File \"/usr/local/lib/python3.9/site-packages/tenacity/__init__.py\", line 379, in __call__\n    do = self.iter(retry_state=retry_state)\n  File \"/usr/local/lib/python3.9/site-packages/tenacity/__init__.py\", line 326, in iter\n    raise retry_exc from fut.exception()\ntenacity.RetryError: RetryError[<Future at 0x7febbf02f7c0 state=finished raised MissingSchema>]\n",
  "ERROR ingesting 'TESTCCLW.executive.1332.1554': Traceback (most recent call last):\n  File \"/usr/local/lib/python3.9/site-packages/tenacity/__init__.py\", line 382, in __call__\n    result = fn(*args, **kwargs)\n  File \"/navigator-data-ingest/src/navigator_data_ingest/base/api_client.py\", line 175, in update_document_details\n    token = get_machine_user_token()\n  File \"/navigator-data-ingest/src/navigator_data_ingest/base/api_client.py\", line 49, in get_machine_user_token\n    get_token_response = requests.post(f\"{api_host}/api/tokens\", data=login_data)\n  File \"/usr/local/lib/python3.9/site-packages/requests/api.py\", line 115, in post\n    return request(\"post\", url, data=data, json=json, **kwargs)\n  File \"/usr/local/lib/python3.9/site-packages/requests/api.py\", line 59, in request\n    return session.request(method=method, url=url, **kwargs)\n  File \"/usr/local/lib/python3.9/site-packages/requests/sessions.py\", line 573, in request\n    prep = self.prepare_request(req)\n  File \"/usr/local/lib/python3.9/site-packages/requests/sessions.py\", line 484, in prepare_request\n    p.prepare(\n  File \"/usr/local/lib/python3.9/site-packages/requests/models.py\", line 368, in prepare\n    self.prepare_url(url, params)\n  File \"/usr/local/lib/python3.9/site-packages/requests/models.py\", line 439, in prepare_url\n    raise MissingSchema(\nrequests.exceptions.MissingSchema: Invalid URL '/api/tokens': No scheme supplied. Perhaps you meant https:///api/tokens?\n\nThe above exception was the direct cause of the following exception:\n\nTraceback (most recent call last):\n  File \"/navigator-data-ingest/src/navigator_data_ingest/base/new_document_actions.py\", line 142, in _handle_document\n    update_document_details(\n  File \"/usr/local/lib/python3.9/site-packages/tenacity/__init__.py\", line 289, in wrapped_f\n    return self(f, *args, **kw)\n  File \"/usr/local/lib/python3.9/site-packages/tenacity/__init__.py\", line 379, in __call__\n    do = self.iter(retry_state=retry_state)\n  File \"/usr/local/lib/python3.9/site-packages/tenacity/__init__.py\", line 326, in iter\n    raise retry_exc from fut.exception()\ntenacity.RetryError: RetryError[<Future at 0x7febbeff9f40 state=finished raised MissingSchema>]\n",
  "ERROR ingesting 'TESTCCLW.executive.1332.1553': Traceback (most recent call last):\n  File \"/usr/local/lib/python3.9/site-packages/tenacity/__init__.py\", line 382, in __call__\n    result = fn(*args, **kwargs)\n  File \"/navigator-data-ingest/src/navigator_data_ingest/base/api_client.py\", line 175, in update_document_details\n    token = get_machine_user_token()\n  File \"/navigator-data-ingest/src/navigator_data_ingest/base/api_client.py\", line 49, in get_machine_user_token\n    get_token_response = requests.post(f\"{api_host}/api/tokens\", data=login_data)\n  File \"/usr/local/lib/python3.9/site-packages/requests/api.py\", line 115, in post\n    return request(\"post\", url, data=data, json=json, **kwargs)\n  File \"/usr/local/lib/python3.9/site-packages/requests/api.py\", line 59, in request\n    return session.request(method=method, url=url, **kwargs)\n  File \"/usr/local/lib/python3.9/site-packages/requests/sessions.py\", line 573, in request\n    prep = self.prepare_request(req)\n  File \"/usr/local/lib/python3.9/site-packages/requests/sessions.py\", line 484, in prepare_request\n    p.prepare(\n  File \"/usr/local/lib/python3.9/site-packages/requests/models.py\", line 368, in prepare\n    self.prepare_url(url, params)\n  File \"/usr/local/lib/python3.9/site-packages/requests/models.py\", line 439, in prepare_url\n    raise MissingSchema(\nrequests.exceptions.MissingSchema: Invalid URL '/api/tokens': No scheme supplied. Perhaps you meant https:///api/tokens?\n\nThe above exception was the direct cause of the following exception:\n\nTraceback (most recent call last):\n  File \"/navigator-data-ingest/src/navigator_data_ingest/base/new_document_actions.py\", line 142, in _handle_document\n    update_document_details(\n  File \"/usr/local/lib/python3.9/site-packages/tenacity/__init__.py\", line 289, in wrapped_f\n    return self(f, *args, **kw)\n  File \"/usr/local/lib/python3.9/site-packages/tenacity/__init__.py\", line 379, in __call__\n    do = self.iter(retry_state=retry_state)\n  File \"/usr/local/lib/python3.9/site-packages/tenacity/__init__.py\", line 326, in iter\n    raise retry_exc from fut.exception()\ntenacity.RetryError: RetryError[<Future at 0x7febbf0aea60 state=finished raised MissingSchema>]\n",
  "ERROR ingesting 'TESTCCLW.executive.1332.1555': Traceback (most recent call last):\n  File \"/usr/local/lib/python3.9/site-packages/tenacity/__init__.py\", line 382, in __call__\n    result = fn(*args, **kwargs)\n  File \"/navigator-data-ingest/src/navigator_data_ingest/base/api_client.py\", line 175, in update_document_details\n    token = get_machine_user_token()\n  File \"/navigator-data-ingest/src/navigator_data_ingest/base/api_client.py\", line 49, in get_machine_user_token\n    get_token_response = requests.post(f\"{api_host}/api/tokens\", data=login_data)\n  File \"/usr/local/lib/python3.9/site-packages/requests/api.py\", line 115, in post\n    return request(\"post\", url, data=data, json=json, **kwargs)\n  File \"/usr/local/lib/python3.9/site-packages/requests/api.py\", line 59, in request\n    return session.request(method=method, url=url, **kwargs)\n  File \"/usr/local/lib/python3.9/site-packages/requests/sessions.py\", line 573, in request\n    prep = self.prepare_request(req)\n  File \"/usr/local/lib/python3.9/site-packages/requests/sessions.py\", line 484, in prepare_request\n    p.prepare(\n  File \"/usr/local/lib/python3.9/site-packages/requests/models.py\", line 368, in prepare\n    self.prepare_url(url, params)\n  File \"/usr/local/lib/python3.9/site-packages/requests/models.py\", line 439, in prepare_url\n    raise MissingSchema(\nrequests.exceptions.MissingSchema: Invalid URL '/api/tokens': No scheme supplied. Perhaps you meant https:///api/tokens?\n\nThe above exception was the direct cause of the following exception:\n\nTraceback (most recent call last):\n  File \"/navigator-data-ingest/src/navigator_data_ingest/base/new_document_actions.py\", line 142, in _handle_document\n    update_document_details(\n  File \"/usr/local/lib/python3.9/site-packages/tenacity/__init__.py\", line 289, in wrapped_f\n    return self(f, *args, **kw)\n  File \"/usr/local/lib/python3.9/site-packages/tenacity/__init__.py\", line 379, in __call__\n    do = self.iter(retry_state=retry_state)\n  File \"/usr/local/lib/python3.9/site-packages/tenacity/__init__.py\", line 326, in iter\n    raise retry_exc from fut.exception()\ntenacity.RetryError: RetryError[<Future at 0x7febbdfae3a0 state=finished raised MissingSchema>]\n",
  "ERROR ingesting 'TESTCCLW.executive.1332.1552': Traceback (most recent call last):\n  File \"/usr/local/lib/python3.9/site-packages/tenacity/__init__.py\", line 382, in __call__\n    result = fn(*args, **kwargs)\n  File \"/navigator-data-ingest/src/navigator_data_ingest/base/api_client.py\", line 175, in update_document_details\n    token = get_machine_user_token()\n  File \"/navigator-data-ingest/src/navigator_data_ingest/base/api_client.py\", line 49, in get_machine_user_token\n    get_token_response = requests.post(f\"{api_host}/api/tokens\", data=login_data)\n  File \"/usr/local/lib/python3.9/site-packages/requests/api.py\", line 115, in post\n    return request(\"post\", url, data=data, json=json, **kwargs)\n  File \"/usr/local/lib/python3.9/site-packages/requests/api.py\", line 59, in request\n    return session.request(method=method, url=url, **kwargs)\n  File \"/usr/local/lib/python3.9/site-packages/requests/sessions.py\", line 573, in request\n    prep = self.prepare_request(req)\n  File \"/usr/local/lib/python3.9/site-packages/requests/sessions.py\", line 484, in prepare_request\n    p.prepare(\n  File \"/usr/local/lib/python3.9/site-packages/requests/models.py\", line 368, in prepare\n    self.prepare_url(url, params)\n  File \"/usr/local/lib/python3.9/site-packages/requests/models.py\", line 439, in prepare_url\n    raise MissingSchema(\nrequests.exceptions.MissingSchema: Invalid URL '/api/tokens': No scheme supplied. Perhaps you meant https:///api/tokens?\n\nThe above exception was the direct cause of the following exception:\n\nTraceback (most recent call last):\n  File \"/navigator-data-ingest/src/navigator_data_ingest/base/new_document_actions.py\", line 142, in _handle_document\n    update_document_details(\n  File \"/usr/local/lib/python3.9/site-packages/tenacity/__init__.py\", line 289, in wrapped_f\n    return self(f, *args, **kw)\n  File \"/usr/local/lib/python3.9/site-packages/tenacity/__init__.py\", line 379, in __call__\n    do = self.iter(retry_state=retry_state)\n  File \"/usr/local/lib/python3.9/site-packages/tenacity/__init__.py\", line 326, in iter\n    raise retry_exc from fut.exception()\ntenacity.RetryError: RetryError[<Future at 0x7febbdf22a90 state=finished raised MissingSchema>]\n",
  "ERROR ingesting 'TESTCCLW.executive.1332.1556': Traceback (most recent call last):\n  File \"/usr/local/lib/python3.9/site-packages/tenacity/__init__.py\", line 382, in __call__\n    result = fn(*args, **kwargs)\n  File \"/navigator-data-ingest/src/navigator_data_ingest/base/api_client.py\", line 175, in update_document_details\n    token = get_machine_user_token()\n  File \"/navigator-data-ingest/src/navigator_data_ingest/base/api_client.py\", line 49, in get_machine_user_token\n    get_token_response = requests.post(f\"{api_host}/api/tokens\", data=login_data)\n  File \"/usr/local/lib/python3.9/site-packages/requests/api.py\", line 115, in post\n    return request(\"post\", url, data=data, json=json, **kwargs)\n  File \"/usr/local/lib/python3.9/site-packages/requests/api.py\", line 59, in request\n    return session.request(method=method, url=url, **kwargs)\n  File \"/usr/local/lib/python3.9/site-packages/requests/sessions.py\", line 573, in request\n    prep = self.prepare_request(req)\n  File \"/usr/local/lib/python3.9/site-packages/requests/sessions.py\", line 484, in prepare_request\n    p.prepare(\n  File \"/usr/local/lib/python3.9/site-packages/requests/models.py\", line 368, in prepare\n    self.prepare_url(url, params)\n  File \"/usr/local/lib/python3.9/site-packages/requests/models.py\", line 439, in prepare_url\n    raise MissingSchema(\nrequests.exceptions.MissingSchema: Invalid URL '/api/tokens': No scheme supplied. Perhaps you meant https:///api/tokens?\n\nThe above exception was the direct cause of the following exception:\n\nTraceback (most recent call last):\n  File \"/navigator-data-ingest/src/navigator_data_ingest/base/new_document_actions.py\", line 142, in _handle_document\n    update_document_details(\n  File \"/usr/local/lib/python3.9/site-packages/tenacity/__init__.py\", line 289, in wrapped_f\n    return self(f, *args, **kw)\n  File \"/usr/local/lib/python3.9/site-packages/tenacity/__init__.py\", line 379, in __call__\n    do = self.iter(retry_state=retry_state)\n  File \"/usr/local/lib/python3.9/site-packages/tenacity/__init__.py\", line 326, in iter\n    raise retry_exc from fut.exception()\ntenacity.RetryError: RetryError[<Future at 0x7febbdfb0c10 state=finished raised MissingSchema>]\n",
  "ERROR ingesting 'TESTCCLW.executive.1332.1559': Traceback (most recent call last):\n  File \"/usr/local/lib/python3.9/site-packages/tenacity/__init__.py\", line 382, in __call__\n    result = fn(*args, **kwargs)\n  File \"/navigator-data-ingest/src/navigator_data_ingest/base/api_client.py\", line 175, in update_document_details\n    token = get_machine_user_token()\n  File \"/navigator-data-ingest/src/navigator_data_ingest/base/api_client.py\", line 49, in get_machine_user_token\n    get_token_response = requests.post(f\"{api_host}/api/tokens\", data=login_data)\n  File \"/usr/local/lib/python3.9/site-packages/requests/api.py\", line 115, in post\n    return request(\"post\", url, data=data, json=json, **kwargs)\n  File \"/usr/local/lib/python3.9/site-packages/requests/api.py\", line 59, in request\n    return session.request(method=method, url=url, **kwargs)\n  File \"/usr/local/lib/python3.9/site-packages/requests/sessions.py\", line 573, in request\n    prep = self.prepare_request(req)\n  File \"/usr/local/lib/python3.9/site-packages/requests/sessions.py\", line 484, in prepare_request\n    p.prepare(\n  File \"/usr/local/lib/python3.9/site-packages/requests/models.py\", line 368, in prepare\n    self.prepare_url(url, params)\n  File \"/usr/local/lib/python3.9/site-packages/requests/models.py\", line 439, in prepare_url\n    raise MissingSchema(\nrequests.exceptions.MissingSchema: Invalid URL '/api/tokens': No scheme supplied. Perhaps you meant https:///api/tokens?\n\nThe above exception was the direct cause of the following exception:\n\nTraceback (most recent call last):\n  File \"/navigator-data-ingest/src/navigator_data_ingest/base/new_document_actions.py\", line 142, in _handle_document\n    update_document_details(\n  File \"/usr/local/lib/python3.9/site-packages/tenacity/__init__.py\", line 289, in wrapped_f\n    return self(f, *args, **kw)\n  File \"/usr/local/lib/python3.9/site-packages/tenacity/__init__.py\", line 379, in __call__\n    do = self.iter(retry_state=retry_state)\n  File \"/usr/local/lib/python3.9/site-packages/tenacity/__init__.py\", line 326, in iter\n    raise retry_exc from fut.exception()\ntenacity.RetryError: RetryError[<Future at 0x7febbdf2cbe0 state=finished raised MissingSchema>]\n",
  "ERROR ingesting 'TESTCCLW.executive.1332.1558': Traceback (most recent call last):\n  File \"/usr/local/lib/python3.9/site-packages/tenacity/__init__.py\", line 382, in __call__\n    result = fn(*args, **kwargs)\n  File \"/navigator-data-ingest/src/navigator_data_ingest/base/api_client.py\", line 175, in update_document_details\n    token = get_machine_user_token()\n  File \"/navigator-data-ingest/src/navigator_data_ingest/base/api_client.py\", line 49, in get_machine_user_token\n    get_token_response = requests.post(f\"{api_host}/api/tokens\", data=login_data)\n  File \"/usr/local/lib/python3.9/site-packages/requests/api.py\", line 115, in post\n    return request(\"post\", url, data=data, json=json, **kwargs)\n  File \"/usr/local/lib/python3.9/site-packages/requests/api.py\", line 59, in request\n    return session.request(method=method, url=url, **kwargs)\n  File \"/usr/local/lib/python3.9/site-packages/requests/sessions.py\", line 573, in request\n    prep = self.prepare_request(req)\n  File \"/usr/local/lib/python3.9/site-packages/requests/sessions.py\", line 484, in prepare_request\n    p.prepare(\n  File \"/usr/local/lib/python3.9/site-packages/requests/models.py\", line 368, in prepare\n    self.prepare_url(url, params)\n  File \"/usr/local/lib/python3.9/site-packages/requests/models.py\", line 439, in prepare_url\n    raise MissingSchema(\nrequests.exceptions.MissingSchema: Invalid URL '/api/tokens': No scheme supplied. Perhaps you meant https:///api/tokens?\n\nThe above exception was the direct cause of the following exception:\n\nTraceback (most recent call last):\n  File \"/navigator-data-ingest/src/navigator_data_ingest/base/new_document_actions.py\", line 142, in _handle_document\n    update_document_details(\n  File \"/usr/local/lib/python3.9/site-packages/tenacity/__init__.py\", line 289, in wrapped_f\n    return self(f, *args, **kw)\n  File \"/usr/local/lib/python3.9/site-packages/tenacity/__init__.py\", line 379, in __call__\n    do = self.iter(retry_state=retry_state)\n  File \"/usr/local/lib/python3.9/site-packages/tenacity/__init__.py\", line 326, in iter\n    raise retry_exc from fut.exception()\ntenacity.RetryError: RetryError[<Future at 0x7febbdf0d280 state=finished raised MissingSchema>]\n",
  "ERROR ingesting 'TESTCCLW.executive.1332.1557': Traceback (most recent call last):\n  File \"/usr/local/lib/python3.9/site-packages/tenacity/__init__.py\", line 382, in __call__\n    result = fn(*args, **kwargs)\n  File \"/navigator-data-ingest/src/navigator_data_ingest/base/api_client.py\", line 175, in update_document_details\n    token = get_machine_user_token()\n  File \"/navigator-data-ingest/src/navigator_data_ingest/base/api_client.py\", line 49, in get_machine_user_token\n    get_token_response = requests.post(f\"{api_host}/api/tokens\", data=login_data)\n  File \"/usr/local/lib/python3.9/site-packages/requests/api.py\", line 115, in post\n    return request(\"post\", url, data=data, json=json, **kwargs)\n  File \"/usr/local/lib/python3.9/site-packages/requests/api.py\", line 59, in request\n    return session.request(method=method, url=url, **kwargs)\n  File \"/usr/local/lib/python3.9/site-packages/requests/sessions.py\", line 573, in request\n    prep = self.prepare_request(req)\n  File \"/usr/local/lib/python3.9/site-packages/requests/sessions.py\", line 484, in prepare_request\n    p.prepare(\n  File \"/usr/local/lib/python3.9/site-packages/requests/models.py\", line 368, in prepare\n    self.prepare_url(url, params)\n  File \"/usr/local/lib/python3.9/site-packages/requests/models.py\", line 439, in prepare_url\n    raise MissingSchema(\nrequests.exceptions.MissingSchema: Invalid URL '/api/tokens': No scheme supplied. Perhaps you meant https:///api/tokens?\n\nThe above exception was the direct cause of the following exception:\n\nTraceback (most recent call last):\n  File \"/navigator-data-ingest/src/navigator_data_ingest/base/new_document_actions.py\", line 142, in _handle_document\n    update_document_details(\n  File \"/usr/local/lib/python3.9/site-packages/tenacity/__init__.py\", line 289, in wrapped_f\n    return self(f, *args, **kw)\n  File \"/usr/local/lib/python3.9/site-packages/tenacity/__init__.py\", line 379, in __call__\n    do = self.iter(retry_state=retry_state)\n  File \"/usr/local/lib/python3.9/site-packages/tenacity/__init__.py\", line 326, in iter\n    raise retry_exc from fut.exception()\ntenacity.RetryError: RetryError[<Future at 0x7febbf0b3880 state=finished raised MissingSchema>]\n",
  "ERROR ingesting 'TESTCCLW.executive.1332.1560': Traceback (most recent call last):\n  File \"/usr/local/lib/python3.9/site-packages/tenacity/__init__.py\", line 382, in __call__\n    result = fn(*args, **kwargs)\n  File \"/navigator-data-ingest/src/navigator_data_ingest/base/api_client.py\", line 175, in update_document_details\n    token = get_machine_user_token()\n  File \"/navigator-data-ingest/src/navigator_data_ingest/base/api_client.py\", line 49, in get_machine_user_token\n    get_token_response = requests.post(f\"{api_host}/api/tokens\", data=login_data)\n  File \"/usr/local/lib/python3.9/site-packages/requests/api.py\", line 115, in post\n    return request(\"post\", url, data=data, json=json, **kwargs)\n  File \"/usr/local/lib/python3.9/site-packages/requests/api.py\", line 59, in request\n    return session.request(method=method, url=url, **kwargs)\n  File \"/usr/local/lib/python3.9/site-packages/requests/sessions.py\", line 573, in request\n    prep = self.prepare_request(req)\n  File \"/usr/local/lib/python3.9/site-packages/requests/sessions.py\", line 484, in prepare_request\n    p.prepare(\n  File \"/usr/local/lib/python3.9/site-packages/requests/models.py\", line 368, in prepare\n    self.prepare_url(url, params)\n  File \"/usr/local/lib/python3.9/site-packages/requests/models.py\", line 439, in prepare_url\n    raise MissingSchema(\nrequests.exceptions.MissingSchema: Invalid URL '/api/tokens': No scheme supplied. Perhaps you meant https:///api/tokens?\n\nThe above exception was the direct cause of the following exception:\n\nTraceback (most recent call last):\n  File \"/navigator-data-ingest/src/navigator_data_ingest/base/new_document_actions.py\", line 142, in _handle_document\n    update_document_details(\n  File \"/usr/local/lib/python3.9/site-packages/tenacity/__init__.py\", line 289, in wrapped_f\n    return self(f, *args, **kw)\n  File \"/usr/local/lib/python3.9/site-packages/tenacity/__init__.py\", line 379, in __call__\n    do = self.iter(retry_state=retry_state)\n  File \"/usr/local/lib/python3.9/site-packages/tenacity/__init__.py\", line 326, in iter\n    raise retry_exc from fut.exception()\ntenacity.RetryError: RetryError[<Future at 0x7febbf0b3b20 state=finished raised MissingSchema>]\n",
  "ERROR ingesting 'TESTCCLW.executive.1332.1562': Traceback (most recent call last):\n  File \"/usr/local/lib/python3.9/site-packages/tenacity/__init__.py\", line 382, in __call__\n    result = fn(*args, **kwargs)\n  File \"/navigator-data-ingest/src/navigator_data_ingest/base/api_client.py\", line 175, in update_document_details\n    token = get_machine_user_token()\n  File \"/navigator-data-ingest/src/navigator_data_ingest/base/api_client.py\", line 49, in get_machine_user_token\n    get_token_response = requests.post(f\"{api_host}/api/tokens\", data=login_data)\n  File \"/usr/local/lib/python3.9/site-packages/requests/api.py\", line 115, in post\n    return request(\"post\", url, data=data, json=json, **kwargs)\n  File \"/usr/local/lib/python3.9/site-packages/requests/api.py\", line 59, in request\n    return session.request(method=method, url=url, **kwargs)\n  File \"/usr/local/lib/python3.9/site-packages/requests/sessions.py\", line 573, in request\n    prep = self.prepare_request(req)\n  File \"/usr/local/lib/python3.9/site-packages/requests/sessions.py\", line 484, in prepare_request\n    p.prepare(\n  File \"/usr/local/lib/python3.9/site-packages/requests/models.py\", line 368, in prepare\n    self.prepare_url(url, params)\n  File \"/usr/local/lib/python3.9/site-packages/requests/models.py\", line 439, in prepare_url\n    raise MissingSchema(\nrequests.exceptions.MissingSchema: Invalid URL '/api/tokens': No scheme supplied. Perhaps you meant https:///api/tokens?\n\nThe above exception was the direct cause of the following exception:\n\nTraceback (most recent call last):\n  File \"/navigator-data-ingest/src/navigator_data_ingest/base/new_document_actions.py\", line 142, in _handle_document\n    update_document_details(\n  File \"/usr/local/lib/python3.9/site-packages/tenacity/__init__.py\", line 289, in wrapped_f\n    return self(f, *args, **kw)\n  File \"/usr/local/lib/python3.9/site-packages/tenacity/__init__.py\", line 379, in __call__\n    do = self.iter(retry_state=retry_state)\n  File \"/usr/local/lib/python3.9/site-packages/tenacity/__init__.py\", line 326, in iter\n    raise retry_exc from fut.exception()\ntenacity.RetryError: RetryError[<Future at 0x7febbdf33790 state=finished raised MissingSchema>]\n",
  "ERROR ingesting 'TESTCCLW.executive.1332.1563': Traceback (most recent call last):\n  File \"/usr/local/lib/python3.9/site-packages/tenacity/__init__.py\", line 382, in __call__\n    result = fn(*args, **kwargs)\n  File \"/navigator-data-ingest/src/navigator_data_ingest/base/api_client.py\", line 175, in update_document_details\n    token = get_machine_user_token()\n  File \"/navigator-data-ingest/src/navigator_data_ingest/base/api_client.py\", line 49, in get_machine_user_token\n    get_token_response = requests.post(f\"{api_host}/api/tokens\", data=login_data)\n  File \"/usr/local/lib/python3.9/site-packages/requests/api.py\", line 115, in post\n    return request(\"post\", url, data=data, json=json, **kwargs)\n  File \"/usr/local/lib/python3.9/site-packages/requests/api.py\", line 59, in request\n    return session.request(method=method, url=url, **kwargs)\n  File \"/usr/local/lib/python3.9/site-packages/requests/sessions.py\", line 573, in request\n    prep = self.prepare_request(req)\n  File \"/usr/local/lib/python3.9/site-packages/requests/sessions.py\", line 484, in prepare_request\n    p.prepare(\n  File \"/usr/local/lib/python3.9/site-packages/requests/models.py\", line 368, in prepare\n    self.prepare_url(url, params)\n  File \"/usr/local/lib/python3.9/site-packages/requests/models.py\", line 439, in prepare_url\n    raise MissingSchema(\nrequests.exceptions.MissingSchema: Invalid URL '/api/tokens': No scheme supplied. Perhaps you meant https:///api/tokens?\n\nThe above exception was the direct cause of the following exception:\n\nTraceback (most recent call last):\n  File \"/navigator-data-ingest/src/navigator_data_ingest/base/new_document_actions.py\", line 142, in _handle_document\n    update_document_details(\n  File \"/usr/local/lib/python3.9/site-packages/tenacity/__init__.py\", line 289, in wrapped_f\n    return self(f, *args, **kw)\n  File \"/usr/local/lib/python3.9/site-packages/tenacity/__init__.py\", line 379, in __call__\n    do = self.iter(retry_state=retry_state)\n  File \"/usr/local/lib/python3.9/site-packages/tenacity/__init__.py\", line 326, in iter\n    raise retry_exc from fut.exception()\ntenacity.RetryError: RetryError[<Future at 0x7febbf0389a0 state=finished raised MissingSchema>]\n",
  "ERROR ingesting 'TESTCCLW.executive.3.3': Traceback (most recent call last):\n  File \"/usr/local/lib/python3.9/site-packages/tenacity/__init__.py\", line 382, in __call__\n    result = fn(*args, **kwargs)\n  File \"/navigator-data-ingest/src/navigator_data_ingest/base/api_client.py\", line 175, in update_document_details\n    token = get_machine_user_token()\n  File \"/navigator-data-ingest/src/navigator_data_ingest/base/api_client.py\", line 49, in get_machine_user_token\n    get_token_response = requests.post(f\"{api_host}/api/tokens\", data=login_data)\n  File \"/usr/local/lib/python3.9/site-packages/requests/api.py\", line 115, in post\n    return request(\"post\", url, data=data, json=json, **kwargs)\n  File \"/usr/local/lib/python3.9/site-packages/requests/api.py\", line 59, in request\n    return session.request(method=method, url=url, **kwargs)\n  File \"/usr/local/lib/python3.9/site-packages/requests/sessions.py\", line 573, in request\n    prep = self.prepare_request(req)\n  File \"/usr/local/lib/python3.9/site-packages/requests/sessions.py\", line 484, in prepare_request\n    p.prepare(\n  File \"/usr/local/lib/python3.9/site-packages/requests/models.py\", line 368, in prepare\n    self.prepare_url(url, params)\n  File \"/usr/local/lib/python3.9/site-packages/requests/models.py\", line 439, in prepare_url\n    raise MissingSchema(\nrequests.exceptions.MissingSchema: Invalid URL '/api/tokens': No scheme supplied. Perhaps you meant https:///api/tokens?\n\nThe above exception was the direct cause of the following exception:\n\nTraceback (most recent call last):\n  File \"/navigator-data-ingest/src/navigator_data_ingest/base/new_document_actions.py\", line 142, in _handle_document\n    update_document_details(\n  File \"/usr/local/lib/python3.9/site-packages/tenacity/__init__.py\", line 289, in wrapped_f\n    return self(f, *args, **kw)\n  File \"/usr/local/lib/python3.9/site-packages/tenacity/__init__.py\", line 379, in __call__\n    do = self.iter(retry_state=retry_state)\n  File \"/usr/local/lib/python3.9/site-packages/tenacity/__init__.py\", line 326, in iter\n    raise retry_exc from fut.exception()\ntenacity.RetryError: RetryError[<Future at 0x7febbf0ca6a0 state=finished raised MissingSchema>]\n",
  "ERROR ingesting 'TESTCCLW.executive.4.4': Traceback (most recent call last):\n  File \"/usr/local/lib/python3.9/site-packages/tenacity/__init__.py\", line 382, in __call__\n    result = fn(*args, **kwargs)\n  File \"/navigator-data-ingest/src/navigator_data_ingest/base/api_client.py\", line 175, in update_document_details\n    token = get_machine_user_token()\n  File \"/navigator-data-ingest/src/navigator_data_ingest/base/api_client.py\", line 49, in get_machine_user_token\n    get_token_response = requests.post(f\"{api_host}/api/tokens\", data=login_data)\n  File \"/usr/local/lib/python3.9/site-packages/requests/api.py\", line 115, in post\n    return request(\"post\", url, data=data, json=json, **kwargs)\n  File \"/usr/local/lib/python3.9/site-packages/requests/api.py\", line 59, in request\n    return session.request(method=method, url=url, **kwargs)\n  File \"/usr/local/lib/python3.9/site-packages/requests/sessions.py\", line 573, in request\n    prep = self.prepare_request(req)\n  File \"/usr/local/lib/python3.9/site-packages/requests/sessions.py\", line 484, in prepare_request\n    p.prepare(\n  File \"/usr/local/lib/python3.9/site-packages/requests/models.py\", line 368, in prepare\n    self.prepare_url(url, params)\n  File \"/usr/local/lib/python3.9/site-packages/requests/models.py\", line 439, in prepare_url\n    raise MissingSchema(\nrequests.exceptions.MissingSchema: Invalid URL '/api/tokens': No scheme supplied. Perhaps you meant https:///api/tokens?\n\nThe above exception was the direct cause of the following exception:\n\nTraceback (most recent call last):\n  File \"/navigator-data-ingest/src/navigator_data_ingest/base/new_document_actions.py\", line 142, in _handle_document\n    update_document_details(\n  File \"/usr/local/lib/python3.9/site-packages/tenacity/__init__.py\", line 289, in wrapped_f\n    return self(f, *args, **kw)\n  File \"/usr/local/lib/python3.9/site-packages/tenacity/__init__.py\", line 379, in __call__\n    do = self.iter(retry_state=retry_state)\n  File \"/usr/local/lib/python3.9/site-packages/tenacity/__init__.py\", line 326, in iter\n    raise retry_exc from fut.exception()\ntenacity.RetryError: RetryError[<Future at 0x7febbdf9a910 state=finished raised MissingSchema>]\n"
]